Workbook

Sheet Assumptions
A1: Parameter | B1: Value | C1: Unit | D1: Source / Notes
A2: STATION ECONOMICS
A3: CapEx per Station | B3: 200000 | C3: USD | D3: Midpoint BoM — telescope $39K, mount $14K, DM $40K, rest
A4: OpEx per Station per Year | B4: 50000 | C4: USD | D4: Power $4K, lease $3.5K, fiber $9K, maint $7K, person $18K, etc.
A5: CapEx Amortization Period | B5: 5 | C5: years | D5: Straight-line
A6: DEPLOYMENT SCHEDULE
A7: Stations Deployed Year 1 | B7: 1 | C7: stations | D7: Challakere: home ground deployment
A8: Stations Deployed Year 2 | B8: 2 | C8: stations | D8: Leh + Jodhpur: desert + high-altitude
A9: Stations Deployed Years 3-5 | B9: 2 | C9: stations | D9: Sriharikota + Shillong: coastal + NE
A10: REVENUE (bottoms-up customer model)
A11: OGS Customers Year 1 | B11: 0 | C11: customers | D11: Still building/demoing first satellite downlink
A12: OGS Customers Year 2 | B12: 1 | C12: customers | D12: 1 pilot customer (e.g., Pixxel test downlink)
A13: OGS Customers Year 3 | B13: 3 | C13: customers | D13: 2-3 early adopter satellite operators
A14: OGS Customers Year 4 | B14: 5 | C14: customers | D14: Growing commercial adoption
A15: OGS Customers Year 5 | B15: 8 | C15: customers | D15: Expanding customer base
A16: ARPU (Annual Revenue per Customer) | B16: 150000 | C16: USD/yr | D16: ~$12.5K/mo per customer = ~11% of station capacity at $1/GB
A17: Data Price per GB | B17: 1 | C17: USD | D17: Qosmic pricing; competitive vs RF $3-17/GB
A18: GB per Pass | B18: 750 | C18: GB | D18: 10 Gbps x 10 min x 60s / 8 bits
A19: Passes per Day per Station | B19: 5 | C19: passes | D19: LEO 500km: typical 5 passes/day ~10 min each
A20: CLOUD MODEL (FROM PART A)
A21: Cloud Avail (5 stations) | B21: 0.995 | C21: fraction | D21: Part A: 5 stations >99% clear-sky availability
A22: Cloud Avail (1 station) | B22: 0.46 | C22: fraction | D22: Part A: Challakere alone = 46%
A23: HARDWARE SALES
A24: HW Units Year 3 | B24: 0 | C24: units | D24: No sales yet — need proven track record
A25: HW Units Year 4 | B25: 1 | C25: units | D25: First turnkey sale (govt/research customer)
A26: HW Units Year 5 | B26: 2 | C26: units | D26: Growing interest; 2 stations
A27: Hardware Price per Unit | B27: 350000 | C27: USD | D27: Standard 50cm OGS at ~1.75x BoM
A28: NQM / GOVT CONTRACTS
A29: NQM Year 1 | B29: 200000 | C29: USD | D29: Phase 1 PoC contract
A30: NQM Year 2 | B30: 400000 | C30: USD | D30: Phase 1 delivery + milestone
A31: NQM Year 3 | B31: 600000 | C31: USD | D31: Phase 2 demonstration
A32: NQM Year 4 | B32: 250000 | C32: USD | D32: Maintenance/support contract
A33: NQM Year 5 | B33: 150000 | C33: USD | D33: Consulting / extension
A34: PARTNER NETWORK (stations.qosmic.space)
A35: Partner Stations Year 1 | B35: 10 | C35: stations | D35: Existing: NASA JPL, ESA, DLR, Aus, Japan, UAE, Norway etc.
A36: Partner Stations Year 2 | B36: 12 | C36: stations | D36: +2 new partner agreements signed
A37: Partner Stations Year 3 | B37: 15 | C37: stations | D37: +3: expanding into Asia-Pacific
A38: Partner Stations Year 4 | B38: 18 | C38: stations | D38: +3: Middle East + Africa
A39: Partner Stations Year 5 | B39: 20 | C39: stations | D39: +2: total 20+ global stations
A40: Partner Passes per Day per Station | B40: 5 | C40: passes | D40: Same orbit geometry as owned stations
...

Sheet Cloud Model from Part A
A1: Station | B1: P_clear | C1: Clear Days/Yr | D1: Notes
A2: Leh | B2: 0.74 | C2: 270 | D2: Winter dip 39%
A3: Jodhpur | B3: 0.78 | C3: 285 | D3: Monsoon dip 50%
A4: Challakere | B4: 0.46 | C4: 168 | D4: Jul dip 8%
A5: Sriharikota | B5: 0.57 | C5: 208 | D5: Coastal monsoon
A6: Shillong | B6: 0.51 | C6: 186 | D6: Heavy monsoon Jun-Sep; Feb 87% clear
A9: Network Availability
A10: 1 station | B10: =B4
A11: 2 stations | B11: =1-(1-B2)*(1-B3)
A12: 3 stations | B12: =1-(1-B2)*(1-B3)*(1-B4)
A13: 5 stations | B13: =1-(1-B2)*(1-B3)*(1-B4)*(1-B5)*(1-B6)
A15: Integration: 5-station result feeds Assumptions B20

Sheet Unit Economics
A1: CapEx per Station
A2: Component | B2: Low | C2: High | D2: Midpoint | E2: Source
A3: Telescope 50cm RC OTA | B3: 35000 | C3: 45000 | D3: 39000 | E3: PlaneWave CDK20
A4: Tracking Mount (direct drive) | B4: 12000 | C4: 16000 | D4: 14000 | E4: ASA DDM85 Basic: $14K
A5: Fast Steering Mirror | B5: 3000 | C5: 8000 | D5: 5500 | E5: Optotune/PI FSM
A6: Deformable Mirror (20x20) | B6: 30000 | C6: 50000 | D6: 40000 | E6: BMC/ALPAO est.
A7: Wavefront Sensor (SH) | B7: 4000 | C7: 7000 | D7: 5500 | E7: Thorlabs WFS31 €4,261
A8: Fiber Coupling Optics | B8: 5000 | C8: 10000 | D8: 7500 | E8: Thorlabs FiberPorts
A9: Receiver Electronics | B9: 5000 | C9: 10000 | D9: 7500 | E9: Discovery Semi 10G
A10: Control Computer | B10: 5000 | C10: 8000 | D10: 6500 | E10: Industrial PC+FPGA
A11: Control Software (amort.) | B11: 10000 | C11: 20000 | D11: 15000 | E11: Amortized dev
A12: Site Preparation | B12: 15000 | C12: 20000 | D12: 17500 | E12: India civil works
A13: Fiber Backhaul (last mile) | B13: 15000 | C13: 25000 | D13: 20000 | E13: BSNL fiber build
A14: Integration & Test | B14: 10000 | C14: 15000 | D14: 12500 | E14: Labor+equipment
A15: Total CapEx | D15: =SUM(D3:D14)
A17: OpEx per Station per Year
A18: Item | B18: Annual Cost | C18: Notes
A19: Power (2-3kW) | B19: 4000 | C19: India $0.10-0.15/kWh
A20: Site Lease | B20: 3500 | C20: Rural India
A21: Fiber Backhaul (annual) | B21: 9000 | C21: BSNL ~₹50K/mo
A22: Equipment Maintenance | B22: 7000 | C22: DM recalibration, recoating
A23: Monitoring Personnel (shared) | B23: 18000 | C23: 1 FTE shared 3-5 stations
A24: Software Licenses | B24: 3500 | C24: OS, monitoring
A25: Insurance | B25: 3500 | C25: Equipment+liability
A26: Transport & Logistics | B26: 4000 | C26: Site visits, spares
A27: Total OpEx/Station/Year | B27: =SUM(B19:B26)
A29: Cost Structure at Maturity (5 stations)
A30: Annual OpEx (5 stations) | B30: =5*Assumptions!B4
A31: Annual CapEx amort. | B31: =5*Assumptions!B3/Assumptions!B5
A32: Annual Payroll (15 people at maturity) | B32: =Assumptions!B65*Assumptions!B66
A33: Annual Overhead | B33: =Assumptions!B71
A34: Platform Operations (AWS) | B34: =Assumptions!B59*12
A35: Annual Fixed Cost (~$1,054K at maturity) | B35: =B30+B31+B32+B33+B34
A36: Annual Data Volume (GB) | B36: =5*Assumptions!B18*Assumptions!B19*365*Assumptions!B21
A37: Cost per GB (cents) | B37: =B35/B36*100
A38: Revenue at 40% util, $1/GB | B38: =B36*0.4*Assumptions!B17

Sheet 5-Year P&L
A1: 5-Year P&L — Realistic Scenario
A2: Revenue: OGS-as-a-Service + partner commissions + hardware + NQM. Costs: stations + team + platform.
B3: Year 1 | C3: Year 2 | D3: Year 3 | E3: Year 4 | F3: Year 5
A4: REVENUE
A5: OGS-as-a-Service | B5: =Assumptions!B11*Assumptions!B16 | C5: =Assumptions!B12*Assumptions!B16 | D5: =Assumptions!B13*Assumptions!B16 | E5: =Assumptions!B14*Assumptions!B16 | F5: =Assumptions!B15*Assumptions!B16
A6: Hardware Sales | B6: 0 | C6: 0 | D6: =Assumptions!B24*Assumptions!B27 | E6: =Assumptions!B25*Assumptions!B27 | F6: =Assumptions!B26*Assumptions!B27
A7: Govt/NQM Contracts | B7: =Assumptions!B29 | C7: =Assumptions!B30 | D7: =Assumptions!B31 | E7: =Assumptions!B32 | F7: =Assumptions!B33
A8: Partner Network Commissions | B8: =Assumptions!B35*Assumptions!B41*Assumptions!B40*365*Assumptions!B42*Assumptions!B47 | C8: =Assumptions!B36*Assumptions!B41*Assumptions!B40*365*Assumptions!B43*Assumptions!B47 | D8: =Assumptions!B37*Assumptions!B41*Assumptions!B40*365*Assumptions!B44*Assumptions!B47 | E8: =Assumptions!B38*Assumptions!B41*Assumptions!B40*365*Assumptions!B45*Assumptions!B47 | F8: =Assumptions!B39*Assumptions!B41*Assumptions!B40*365*Assumptions!B46*Assumptions!B47
A9: ZAPHOD Terminal Sales | B9: 0 | C9: =Assumptions!B49*Assumptions!B53 | D9: =Assumptions!B50*Assumptions!B53 | E9: =Assumptions!B51*Assumptions!B53 | F9: =Assumptions!B52*Assumptions!B53
A10: Total Revenue | B10: =SUM(B5:B9) | C10: =SUM(C5:C9) | D10: =SUM(D5:D9) | E10: =SUM(E5:E9) | F10: =SUM(F5:F9)
A11: COSTS
A12: CapEx (new stations) | B12: =(Assumptions!B7)*Assumptions!B3 | C12: =(Assumptions!B8)*Assumptions!B3 | D12: =(Assumptions!B9)*Assumptions!B3 | E12: =(0)*Assumptions!B3 | F12: =(0)*Assumptions!B3
A13: OpEx (cumulative stations) | B13: =(Assumptions!B7)*Assumptions!B4 | C13: =(Assumptions!B7+Assumptions!B8)*Assumptions!B4 | D13: =(Assumptions!B7+Assumptions!B8+Assumptions!B9)*Assumptions!B4 | E13: =(Assumptions!B7+Assumptions!B8+Assumptions!B9)*Assumptions!B4 | F13: =(Assumptions!B7+Assumptions!B8+Assumptions!B9)*Assumptions!B4
A14: Payroll | B14: =Assumptions!B61*Assumptions!B66 | C14: =Assumptions!B62*Assumptions!B66 | D14: =Assumptions!B63*Assumptions!B66 | E14: =Assumptions!B64*Assumptions!B66 | F14: =Assumptions!B65*Assumptions!B66
A15: Corporate Overhead | B15: =Assumptions!B67 | C15: =Assumptions!B68 | D15: =Assumptions!B69 | E15: =Assumptions!B70 | F15: =Assumptions!B71
A16: COGS - Hardware Sales | B16: 0 | C16: 0 | D16: =Assumptions!B24*Assumptions!B3 | E16: =Assumptions!B25*Assumptions!B3 | F16: =Assumptions!B26*Assumptions!B3
A17: Platform Operations (AWS) | B17: =Assumptions!B55*12 | C17: =Assumptions!B56*12 | D17: =Assumptions!B57*12 | E17: =Assumptions!B58*12 | F17: =Assumptions!B59*12
A18: Total Costs | B18: =SUM(B12:B17) | C18: =SUM(C12:C17) | D18: =SUM(D12:D17) | E18: =SUM(E12:E17) | F18: =SUM(F12:F17)
A20: EBITDA (Revenue - Costs) | B20: =B10-B18 | C20: =C10-C18 | D20: =D10-D18 | E20: =E10-E18 | F20: =F10-F18

Sheet Breakeven Sensitivity
A1: Annual OGS Revenue ($K) — Sensitivity: Customers × ARPU
A2: Rows = number of paying customers. Columns = annual revenue per customer ($K).
A3: Fixed costs ~$1,054K/yr at 5-station maturity. Green = revenue > $1,054K.
A5: Customers \ ARPU ($K) | B5: 25 | C5: 50 | D5: 75 | E5: 100 | F5: 150 | G5: 200
A6: 0 | B6: 0 | C6: 0 | D6: 0 | E6: 0 | F6: 0 | G6: 0
A7: 1 | B7: 25 | C7: 50 | D7: 75 | E7: 100 | F7: 150 | G7: 200
A8: 3 | B8: 75 | C8: 150 | D8: 225 | E8: 300 | F8: 450 | G8: 600
A9: 5 | B9: 125 | C9: 250 | D9: 375 | E9: 500 | F9: 750 | G9: 1000
A10: 8 | B10: 200 | C10: 400 | D10: 600 | E10: 800 | F10: 1200 | G10: 1600
A11: 12 | B11: 300 | C11: 600 | D11: 900 | E11: 1200 | F11: 1800 | G11: 2400
A12: 15 | B12: 375 | C12: 750 | D12: 1125 | E12: 1500 | F12: 2250 | G12: 3000

Sheet Investor Summary
A1: Investor Summary — Key Metrics
A2: All values auto-calculated from Assumptions tab
A3: Metric | B3: Value | C3: Notes
A4: MARKET OPPORTUNITY
A5: TAM (GSaaS market, 2030) | B5: $14.2B | C5: Dataintelo: $3.8B->$14.2B (CAGR 15.8%)
A6: Serviceable Market (Optical GSaaS) | B6: ~$200-500M by 2030 | C6: Optical subset of GSaaS, early stage
A8: FINANCIAL PERFORMANCE
A9: Year 3 OGS Revenue | B9: ='5-Year P&L'!C5 | C9: From P&L tab — 3 customers × $150K ARPU
A10: Year 5 OGS Revenue | B10: ='5-Year P&L'!F5 | C10: From P&L tab — 8 customers × $150K ARPU
A11: Year 5 Total Revenue | B11: ='5-Year P&L'!F10 | C11: OGS + partner commissions + HW + NQM + ZAPHOD
A12: Year 5 EBITDA | B12: ='5-Year P&L'!F20 | C12: Revenue minus costs
A13: Year 5 EBITDA Margin | B13: ='5-Year P&L'!F20/'5-Year P&L'!F10 | C13: EBITDA / Total Revenue
A15: CASH & RUNWAY
A16: Seed Round | B16: 1000000 | C16: Per interview document
A17: Monthly Burn (Y1 est.) | B17: 150000 | C17: $120K salaries + $30K OpEx
A18: Est. Runway (months) | B18: =B16/B17 | C18: Seed / Monthly Burn. $150K/mo is top-down total cash spend incl. one-time setup + buffer
A20: FUNDRAISING
A21: Target Series A Raise | B21: $4-6M | C21: Range based on comparable seed->A multiples
A22: Est. Pre-Money Valuation | B22: $15-25M | C22: Discounted for seed-stage; KSAT at ~$150M rev
A23: Est. Post-Money | B23: $19-31M | C23: Pre + Raise
